[W 2025-05-26 22:11:00.364 ServerApp] A `_jupyter_server_extension_points` function was not found in notebook_shim. Instead, a `_jupyter_server_extension_paths` function was found and will be used for now. This function name will be deprecated in future releases of Jupyter Server.
[I 2025-05-26 22:11:00.365 ServerApp] jupyter_lsp | extension was successfully linked.
[I 2025-05-26 22:11:00.369 ServerApp] jupyter_server_mathjax | extension was successfully linked.
[I 2025-05-26 22:11:00.372 ServerApp] jupyter_server_terminals | extension was successfully linked.
[I 2025-05-26 22:11:00.376 ServerApp] jupyterlab | extension was successfully linked.
[I 2025-05-26 22:11:00.376 ServerApp] nbdime | extension was successfully linked.
[I 2025-05-26 22:11:00.380 ServerApp] notebook | extension was successfully linked.
[I 2025-05-26 22:11:00.526 ServerApp] notebook_shim | extension was successfully linked.
[I 2025-05-26 22:11:00.590 ServerApp] notebook_shim | extension was successfully loaded.
[I 2025-05-26 22:11:00.591 ServerApp] jupyter_lsp | extension was successfully loaded.
[I 2025-05-26 22:11:00.592 ServerApp] jupyter_server_mathjax | extension was successfully loaded.
[I 2025-05-26 22:11:00.592 ServerApp] jupyter_server_terminals | extension was successfully loaded.
[I 2025-05-26 22:11:00.594 LabApp] JupyterLab extension loaded from /home/ir739wb/miniconda3/envs/myenv/lib/python3.12/site-packages/jupyterlab
[I 2025-05-26 22:11:00.594 LabApp] JupyterLab application directory is /home/ir739wb/miniconda3/envs/myenv/share/jupyter/lab
[I 2025-05-26 22:11:00.594 LabApp] Extension Manager is 'pypi'.
[I 2025-05-26 22:11:00.622 ServerApp] jupyterlab | extension was successfully loaded.
[I 2025-05-26 22:11:00.657 ServerApp] nbdime | extension was successfully loaded.
[I 2025-05-26 22:11:00.660 ServerApp] notebook | extension was successfully loaded.
[I 2025-05-26 22:11:00.661 ServerApp] The port 8888 is already in use, trying another port.
[I 2025-05-26 22:11:00.661 ServerApp] The port 8889 is already in use, trying another port.
[I 2025-05-26 22:11:00.661 ServerApp] The port 8890 is already in use, trying another port.
[I 2025-05-26 22:11:00.661 ServerApp] The port 8891 is already in use, trying another port.
[I 2025-05-26 22:11:00.661 ServerApp] Serving notebooks from local directory: /home/ir739wb/ilyarekun/bc_project/centralized-learning
[I 2025-05-26 22:11:00.661 ServerApp] Jupyter Server 2.15.0 is running at:
[I 2025-05-26 22:11:00.661 ServerApp] http://DGX:8892/tree?token=c7c9e55faaf9f381de7ef7cbb1c953f94c883fd6eae99fdc
[I 2025-05-26 22:11:00.661 ServerApp]     http://127.0.0.1:8892/tree?token=c7c9e55faaf9f381de7ef7cbb1c953f94c883fd6eae99fdc
[I 2025-05-26 22:11:00.661 ServerApp] Use Control-C to stop this server and shut down all kernels (twice to skip confirmation).
[C 2025-05-26 22:11:00.663 ServerApp] 
    
    To access the server, open this file in a browser:
        file:///home/ir739wb/.local/share/jupyter/runtime/jpserver-4175004-open.html
    Or copy and paste one of these URLs:
        http://DGX:8892/tree?token=c7c9e55faaf9f381de7ef7cbb1c953f94c883fd6eae99fdc
        http://127.0.0.1:8892/tree?token=c7c9e55faaf9f381de7ef7cbb1c953f94c883fd6eae99fdc
[I 2025-05-26 22:11:00.684 ServerApp] Skipped non-installed server(s): bash-language-server, dockerfile-language-server-nodejs, javascript-typescript-langserver, jedi-language-server, julia-language-server, pyright, python-language-server, r-languageserver, sql-language-server, texlab, typescript-language-server, unified-language-server, vscode-css-languageserver-bin, vscode-html-languageserver-bin, vscode-json-languageserver-bin, yaml-language-server
[W 2025-05-26 22:11:11.261 ServerApp] wrote error: 'Forbidden'
    Traceback (most recent call last):
      File "/home/ir739wb/miniconda3/envs/myenv/lib/python3.12/site-packages/tornado/web.py", line 1788, in _execute
        result = method(*self.path_args, **self.path_kwargs)
                 ^^^^^^^^^^^^^^^^^^^^^^^^^^^^^^^^^^^^^^^^^^^
      File "/home/ir739wb/miniconda3/envs/myenv/lib/python3.12/site-packages/tornado/web.py", line 3289, in wrapper
        url = self.get_login_url()
              ^^^^^^^^^^^^^^^^^^^^
      File "/home/ir739wb/miniconda3/envs/myenv/lib/python3.12/site-packages/jupyter_server/base/handlers.py", line 784, in get_login_url
        raise web.HTTPError(403)
    tornado.web.HTTPError: HTTP 403: Forbidden
[W 2025-05-26 22:11:11.263 ServerApp] 403 GET /api/kernels/43afc0ba-1ea8-44ba-b0b9-be467c7745d4?1748290271258 (@127.0.0.1) 2.35ms referer=None
[W 2025-05-26 22:11:13.303 ServerApp] wrote error: 'Forbidden'
    Traceback (most recent call last):
      File "/home/ir739wb/miniconda3/envs/myenv/lib/python3.12/site-packages/tornado/web.py", line 1788, in _execute
        result = method(*self.path_args, **self.path_kwargs)
                 ^^^^^^^^^^^^^^^^^^^^^^^^^^^^^^^^^^^^^^^^^^^
      File "/home/ir739wb/miniconda3/envs/myenv/lib/python3.12/site-packages/tornado/web.py", line 3289, in wrapper
        url = self.get_login_url()
              ^^^^^^^^^^^^^^^^^^^^
      File "/home/ir739wb/miniconda3/envs/myenv/lib/python3.12/site-packages/jupyter_server/base/handlers.py", line 784, in get_login_url
        raise web.HTTPError(403)
    tornado.web.HTTPError: HTTP 403: Forbidden
[W 2025-05-26 22:11:13.304 ServerApp] 403 GET /api/kernelspecs?1748290273297 (@127.0.0.1) 0.73ms referer=None
[W 2025-05-26 22:11:13.304 ServerApp] wrote error: 'Forbidden'
    Traceback (most recent call last):
      File "/home/ir739wb/miniconda3/envs/myenv/lib/python3.12/site-packages/tornado/web.py", line 1788, in _execute
        result = method(*self.path_args, **self.path_kwargs)
                 ^^^^^^^^^^^^^^^^^^^^^^^^^^^^^^^^^^^^^^^^^^^
      File "/home/ir739wb/miniconda3/envs/myenv/lib/python3.12/site-packages/tornado/web.py", line 3289, in wrapper
        url = self.get_login_url()
              ^^^^^^^^^^^^^^^^^^^^
      File "/home/ir739wb/miniconda3/envs/myenv/lib/python3.12/site-packages/jupyter_server/base/handlers.py", line 784, in get_login_url
        raise web.HTTPError(403)
    tornado.web.HTTPError: HTTP 403: Forbidden
[W 2025-05-26 22:11:13.305 ServerApp] 403 GET /api/kernels?1748290273298 (@127.0.0.1) 0.64ms referer=None
[W 2025-05-26 22:11:13.305 ServerApp] wrote error: 'Forbidden'
    Traceback (most recent call last):
      File "/home/ir739wb/miniconda3/envs/myenv/lib/python3.12/site-packages/tornado/web.py", line 1788, in _execute
        result = method(*self.path_args, **self.path_kwargs)
                 ^^^^^^^^^^^^^^^^^^^^^^^^^^^^^^^^^^^^^^^^^^^
      File "/home/ir739wb/miniconda3/envs/myenv/lib/python3.12/site-packages/tornado/web.py", line 3289, in wrapper
        url = self.get_login_url()
              ^^^^^^^^^^^^^^^^^^^^
      File "/home/ir739wb/miniconda3/envs/myenv/lib/python3.12/site-packages/jupyter_server/base/handlers.py", line 784, in get_login_url
        raise web.HTTPError(403)
    tornado.web.HTTPError: HTTP 403: Forbidden
[W 2025-05-26 22:11:13.305 ServerApp] 403 GET /api/sessions?1748290273302 (@127.0.0.1) 0.61ms referer=None
[W 2025-05-26 22:11:13.306 ServerApp] wrote error: 'Forbidden'
    Traceback (most recent call last):
      File "/home/ir739wb/miniconda3/envs/myenv/lib/python3.12/site-packages/tornado/web.py", line 1788, in _execute
        result = method(*self.path_args, **self.path_kwargs)
                 ^^^^^^^^^^^^^^^^^^^^^^^^^^^^^^^^^^^^^^^^^^^
      File "/home/ir739wb/miniconda3/envs/myenv/lib/python3.12/site-packages/tornado/web.py", line 3289, in wrapper
        url = self.get_login_url()
              ^^^^^^^^^^^^^^^^^^^^
      File "/home/ir739wb/miniconda3/envs/myenv/lib/python3.12/site-packages/jupyter_server/base/handlers.py", line 784, in get_login_url
        raise web.HTTPError(403)
    tornado.web.HTTPError: HTTP 403: Forbidden
[W 2025-05-26 22:11:13.306 ServerApp] 403 GET /api/kernels?1748290273301 (@127.0.0.1) 0.55ms referer=None
[W 2025-05-26 22:11:13.309 ServerApp] wrote error: 'Forbidden'
    Traceback (most recent call last):
      File "/home/ir739wb/miniconda3/envs/myenv/lib/python3.12/site-packages/tornado/web.py", line 1788, in _execute
        result = method(*self.path_args, **self.path_kwargs)
                 ^^^^^^^^^^^^^^^^^^^^^^^^^^^^^^^^^^^^^^^^^^^
      File "/home/ir739wb/miniconda3/envs/myenv/lib/python3.12/site-packages/tornado/web.py", line 3289, in wrapper
        url = self.get_login_url()
              ^^^^^^^^^^^^^^^^^^^^
      File "/home/ir739wb/miniconda3/envs/myenv/lib/python3.12/site-packages/jupyter_server/base/handlers.py", line 784, in get_login_url
        raise web.HTTPError(403)
    tornado.web.HTTPError: HTTP 403: Forbidden
[W 2025-05-26 22:11:13.309 ServerApp] 403 GET /api/kernelspecs?1748290273306 (@127.0.0.1) 0.53ms referer=None
[I 2025-05-26 22:11:13.309 ServerApp] 302 GET / (@127.0.0.1) 0.20ms
[I 2025-05-26 22:11:13.311 JupyterNotebookApp] 302 GET /tree? (@127.0.0.1) 0.29ms
[W 2025-05-26 22:11:13.328 ServerApp] wrote error: 'Forbidden'
    Traceback (most recent call last):
      File "/home/ir739wb/miniconda3/envs/myenv/lib/python3.12/site-packages/tornado/web.py", line 1788, in _execute
        result = method(*self.path_args, **self.path_kwargs)
                 ^^^^^^^^^^^^^^^^^^^^^^^^^^^^^^^^^^^^^^^^^^^
      File "/home/ir739wb/miniconda3/envs/myenv/lib/python3.12/site-packages/tornado/web.py", line 3289, in wrapper
        url = self.get_login_url()
              ^^^^^^^^^^^^^^^^^^^^
      File "/home/ir739wb/miniconda3/envs/myenv/lib/python3.12/site-packages/jupyter_server/base/handlers.py", line 784, in get_login_url
        raise web.HTTPError(403)
    tornado.web.HTTPError: HTTP 403: Forbidden
[W 2025-05-26 22:11:13.328 ServerApp] 403 GET /api/kernelspecs?1748290273326 (@127.0.0.1) 0.54ms referer=None
[W 2025-05-26 22:11:13.330 ServerApp] wrote error: 'Forbidden'
    Traceback (most recent call last):
      File "/home/ir739wb/miniconda3/envs/myenv/lib/python3.12/site-packages/tornado/web.py", line 1788, in _execute
        result = method(*self.path_args, **self.path_kwargs)
                 ^^^^^^^^^^^^^^^^^^^^^^^^^^^^^^^^^^^^^^^^^^^
      File "/home/ir739wb/miniconda3/envs/myenv/lib/python3.12/site-packages/tornado/web.py", line 3289, in wrapper
        url = self.get_login_url()
              ^^^^^^^^^^^^^^^^^^^^
      File "/home/ir739wb/miniconda3/envs/myenv/lib/python3.12/site-packages/jupyter_server/base/handlers.py", line 784, in get_login_url
        raise web.HTTPError(403)
    tornado.web.HTTPError: HTTP 403: Forbidden
[W 2025-05-26 22:11:13.330 ServerApp] 403 GET /api/kernels?1748290273326 (@127.0.0.1) 0.55ms referer=None
[W 2025-05-26 22:11:13.331 ServerApp] wrote error: 'Forbidden'
    Traceback (most recent call last):
      File "/home/ir739wb/miniconda3/envs/myenv/lib/python3.12/site-packages/tornado/web.py", line 1788, in _execute
        result = method(*self.path_args, **self.path_kwargs)
                 ^^^^^^^^^^^^^^^^^^^^^^^^^^^^^^^^^^^^^^^^^^^
      File "/home/ir739wb/miniconda3/envs/myenv/lib/python3.12/site-packages/tornado/web.py", line 3289, in wrapper
        url = self.get_login_url()
              ^^^^^^^^^^^^^^^^^^^^
      File "/home/ir739wb/miniconda3/envs/myenv/lib/python3.12/site-packages/jupyter_server/base/handlers.py", line 784, in get_login_url
        raise web.HTTPError(403)
    tornado.web.HTTPError: HTTP 403: Forbidden
[W 2025-05-26 22:11:13.331 ServerApp] 403 GET /api/kernels?1748290273328 (@127.0.0.1) 0.64ms referer=None
[W 2025-05-26 22:11:13.331 ServerApp] wrote error: 'Forbidden'
    Traceback (most recent call last):
      File "/home/ir739wb/miniconda3/envs/myenv/lib/python3.12/site-packages/tornado/web.py", line 1788, in _execute
        result = method(*self.path_args, **self.path_kwargs)
                 ^^^^^^^^^^^^^^^^^^^^^^^^^^^^^^^^^^^^^^^^^^^
      File "/home/ir739wb/miniconda3/envs/myenv/lib/python3.12/site-packages/tornado/web.py", line 3289, in wrapper
        url = self.get_login_url()
              ^^^^^^^^^^^^^^^^^^^^
      File "/home/ir739wb/miniconda3/envs/myenv/lib/python3.12/site-packages/jupyter_server/base/handlers.py", line 784, in get_login_url
        raise web.HTTPError(403)
    tornado.web.HTTPError: HTTP 403: Forbidden
[W 2025-05-26 22:11:13.332 ServerApp] 403 GET /api/sessions?1748290273329 (@127.0.0.1) 1.00ms referer=None
[W 2025-05-26 22:11:13.334 ServerApp] wrote error: 'Forbidden'
    Traceback (most recent call last):
      File "/home/ir739wb/miniconda3/envs/myenv/lib/python3.12/site-packages/tornado/web.py", line 1788, in _execute
        result = method(*self.path_args, **self.path_kwargs)
                 ^^^^^^^^^^^^^^^^^^^^^^^^^^^^^^^^^^^^^^^^^^^
      File "/home/ir739wb/miniconda3/envs/myenv/lib/python3.12/site-packages/tornado/web.py", line 3289, in wrapper
        url = self.get_login_url()
              ^^^^^^^^^^^^^^^^^^^^
      File "/home/ir739wb/miniconda3/envs/myenv/lib/python3.12/site-packages/jupyter_server/base/handlers.py", line 784, in get_login_url
        raise web.HTTPError(403)
    tornado.web.HTTPError: HTTP 403: Forbidden
[W 2025-05-26 22:11:13.334 ServerApp] 403 GET /api/kernelspecs?1748290273331 (@127.0.0.1) 0.51ms referer=None
[I 2025-05-26 22:11:55.143 ServerApp] 302 GET / (@127.0.0.1) 0.39ms
[I 2025-05-26 22:11:55.145 JupyterNotebookApp] 302 GET /tree? (@127.0.0.1) 0.32ms
[I 2025-05-26 22:11:56.416 ServerApp] 302 GET / (@127.0.0.1) 0.22ms
[I 2025-05-26 22:11:56.417 JupyterNotebookApp] 302 GET /tree? (@127.0.0.1) 0.25ms
[I 2025-05-26 22:12:06.451 ServerApp] 302 GET / (@127.0.0.1) 0.31ms
[I 2025-05-26 22:12:06.452 JupyterNotebookApp] 302 GET /tree? (@127.0.0.1) 0.29ms
[I 2025-05-26 22:12:06.497 ServerApp] Kernel started: 0fe8d096-49fe-4d9b-9b7a-c02624673158
[I 2025-05-26 22:12:06.872 ServerApp] Connecting to kernel 0fe8d096-49fe-4d9b-9b7a-c02624673158.
libibverbs: Warning: couldn't load driver 'libvmw_pvrdma-rdmav34.so': libvmw_pvrdma-rdmav34.so: cannot open shared object file: No such file or directory
[I 2025-05-26 22:12:37.853 ServerApp] Kernel interrupted: 0fe8d096-49fe-4d9b-9b7a-c02624673158
[I 2025-05-26 22:28:45.580 ServerApp] Kernel restarted: 0fe8d096-49fe-4d9b-9b7a-c02624673158
[I 2025-05-26 22:28:45.582 ServerApp] Starting buffering for 0fe8d096-49fe-4d9b-9b7a-c02624673158:640e4822-c512-4a95-9cba-94c4382fa048
[I 2025-05-26 22:28:45.587 ServerApp] Connecting to kernel 0fe8d096-49fe-4d9b-9b7a-c02624673158.
[I 2025-05-26 22:28:45.587 ServerApp] Restoring connection for 0fe8d096-49fe-4d9b-9b7a-c02624673158:640e4822-c512-4a95-9cba-94c4382fa048
[I 2025-05-26 22:28:58.587 ServerApp] Kernel restarted: 0fe8d096-49fe-4d9b-9b7a-c02624673158
[I 2025-05-26 22:28:58.590 ServerApp] Starting buffering for 0fe8d096-49fe-4d9b-9b7a-c02624673158:640e4822-c512-4a95-9cba-94c4382fa048
[I 2025-05-26 22:28:58.594 ServerApp] Connecting to kernel 0fe8d096-49fe-4d9b-9b7a-c02624673158.
[I 2025-05-26 22:28:58.594 ServerApp] Restoring connection for 0fe8d096-49fe-4d9b-9b7a-c02624673158:640e4822-c512-4a95-9cba-94c4382fa048
[I 2025-05-26 22:30:35.380 ServerApp] Kernel restarted: 0fe8d096-49fe-4d9b-9b7a-c02624673158
[I 2025-05-26 22:30:35.381 ServerApp] Starting buffering for 0fe8d096-49fe-4d9b-9b7a-c02624673158:640e4822-c512-4a95-9cba-94c4382fa048
[I 2025-05-26 22:30:35.385 ServerApp] Connecting to kernel 0fe8d096-49fe-4d9b-9b7a-c02624673158.
[I 2025-05-26 22:30:35.385 ServerApp] Restoring connection for 0fe8d096-49fe-4d9b-9b7a-c02624673158:640e4822-c512-4a95-9cba-94c4382fa048
[I 2025-05-26 22:32:15.922 ServerApp] Kernel restarted: 0fe8d096-49fe-4d9b-9b7a-c02624673158
[I 2025-05-26 22:32:15.924 ServerApp] Starting buffering for 0fe8d096-49fe-4d9b-9b7a-c02624673158:640e4822-c512-4a95-9cba-94c4382fa048
[I 2025-05-26 22:32:15.928 ServerApp] Connecting to kernel 0fe8d096-49fe-4d9b-9b7a-c02624673158.
[I 2025-05-26 22:32:15.928 ServerApp] Restoring connection for 0fe8d096-49fe-4d9b-9b7a-c02624673158:640e4822-c512-4a95-9cba-94c4382fa048
[I 2025-05-26 22:32:49.381 ServerApp] Kernel restarted: 0fe8d096-49fe-4d9b-9b7a-c02624673158
[I 2025-05-26 22:32:49.383 ServerApp] Starting buffering for 0fe8d096-49fe-4d9b-9b7a-c02624673158:640e4822-c512-4a95-9cba-94c4382fa048
[I 2025-05-26 22:32:49.388 ServerApp] Connecting to kernel 0fe8d096-49fe-4d9b-9b7a-c02624673158.
[I 2025-05-26 22:32:49.388 ServerApp] Restoring connection for 0fe8d096-49fe-4d9b-9b7a-c02624673158:640e4822-c512-4a95-9cba-94c4382fa048
[I 2025-05-26 22:35:27.160 ServerApp] Kernel restarted: 0fe8d096-49fe-4d9b-9b7a-c02624673158
[I 2025-05-26 22:35:27.162 ServerApp] Starting buffering for 0fe8d096-49fe-4d9b-9b7a-c02624673158:640e4822-c512-4a95-9cba-94c4382fa048
[I 2025-05-26 22:35:27.167 ServerApp] Connecting to kernel 0fe8d096-49fe-4d9b-9b7a-c02624673158.
[I 2025-05-26 22:35:27.167 ServerApp] Restoring connection for 0fe8d096-49fe-4d9b-9b7a-c02624673158:640e4822-c512-4a95-9cba-94c4382fa048
[I 2025-05-26 22:36:32.379 ServerApp] Kernel restarted: 0fe8d096-49fe-4d9b-9b7a-c02624673158
[I 2025-05-26 22:36:32.380 ServerApp] Starting buffering for 0fe8d096-49fe-4d9b-9b7a-c02624673158:640e4822-c512-4a95-9cba-94c4382fa048
[I 2025-05-26 22:36:32.386 ServerApp] Connecting to kernel 0fe8d096-49fe-4d9b-9b7a-c02624673158.
[I 2025-05-26 22:36:32.386 ServerApp] Restoring connection for 0fe8d096-49fe-4d9b-9b7a-c02624673158:640e4822-c512-4a95-9cba-94c4382fa048
libibverbs: Warning: couldn't load driver 'libvmw_pvrdma-rdmav34.so': libvmw_pvrdma-rdmav34.so: cannot open shared object file: No such file or directory
[I 2025-05-26 22:37:29.954 ServerApp] Kernel interrupted: 0fe8d096-49fe-4d9b-9b7a-c02624673158
srun: Job step aborted: Waiting up to 32 seconds for job step to finish.
srun: got SIGCONT
slurmstepd-DGX: error: *** STEP 2239.0 ON DGX CANCELLED AT 2025-05-27T01:26:22 ***
slurmstepd-DGX: error: *** JOB 2239 ON DGX CANCELLED AT 2025-05-27T01:26:22 ***
[C 2025-05-27 01:26:22.420 ServerApp] received signal 15, stopping
[I 2025-05-27 01:26:22.421 ServerApp] Shutting down 7 extensions
[I 2025-05-27 01:26:22.421 ServerApp] Shutting down 1 kernel
[I 2025-05-27 01:26:22.422 ServerApp] Kernel shutdown: 0fe8d096-49fe-4d9b-9b7a-c02624673158
srun: forcing job termination
